"POST /api/images/ HTTP/1.1" 500 103073
Internal Server Error: /api/images/
Traceback (most recent call last):
  File "/Users/etaylor/dev/wedding-website/venv/lib/python3.13/site-packages/django/core/handlers/exception.py", line 55, in inner
    response = get_response(request)
  File "/Users/etaylor/dev/wedding-website/venv/lib/python3.13/site-packages/django/core/handlers/base.py", line 197, in _get_response
    response = wrapped_callback(request, *callback_args, **callback_kwargs)
  File "/Users/etaylor/dev/wedding-website/venv/lib/python3.13/site-packages/django/views/decorators/csrf.py", line 65, in _view_wrapper
    return view_func(request, *args, **kwargs)
  File "/Users/etaylor/dev/wedding-website/venv/lib/python3.13/site-packages/django/views/generic/base.py", line 105, in view
    return self.dispatch(request, *args, **kwargs)
           ~~~~~~~~~~~~~^^^^^^^^^^^^^^^^^^^^^^^^^^
  File "/Users/etaylor/dev/wedding-website/venv/lib/python3.13/site-packages/rest_framework/views.py", line 509, in dispatch
    response = self.handle_exception(exc)
  File "/Users/etaylor/dev/wedding-website/venv/lib/python3.13/site-packages/rest_framework/views.py", line 469, in handle_exception
    self.raise_uncaught_exception(exc)
    ~~~~~~~~~~~~~~~~~~~~~~~~~~~~~^^^^^
  File "/Users/etaylor/dev/wedding-website/venv/lib/python3.13/site-packages/rest_framework/views.py", line 480, in raise_uncaught_exception
    raise exc
  File "/Users/etaylor/dev/wedding-website/venv/lib/python3.13/site-packages/rest_framework/views.py", line 506, in dispatch
    response = handler(request, *args, **kwargs)
  File "/Users/etaylor/dev/wedding-website/venv/lib/python3.13/site-packages/rest_framework/generics.py", line 242, in post
    return self.create(request, *args, **kwargs)
           ~~~~~~~~~~~^^^^^^^^^^^^^^^^^^^^^^^^^^
  File "/Users/etaylor/dev/wedding-website/images/views.py", line 54, in create
    user = request.user if request.user.is_authenticated else User.objects.get(username='testuser')
                                                              ~~~~~~~~~~~~~~~~^^^^^^^^^^^^^^^^^^^^^
  File "/Users/etaylor/dev/wedding-website/venv/lib/python3.13/site-packages/django/db/models/manager.py", line 87, in manager_method
    return getattr(self.get_queryset(), name)(*args, **kwargs)
           ~~~~~~~~~~~~~~~~~~~~~~~~~~~~~~~~~~^^^^^^^^^^^^^^^^^
  File "/Users/etaylor/dev/wedding-website/venv/lib/python3.13/site-packages/django/db/models/query.py", line 633, in get
    raise self.model.DoesNotExist(
        "%s matching query does not exist." % self.model._meta.object_name
    )
django.contrib.auth.models.User.DoesNotExist: User matching query does not exist.